<?xml version="1.0"?>
<robot xmlns:xacro="http://www.ros.org/wiki/xacro" name="hambot">

  <!-- ========================================== -->
  <!-- 1. MATERIALS & INERTIAL MACROS             -->
  <!-- ========================================== -->
  <material name="blue"><color rgba="0.1 0.1 0.8 1.0"/></material>
  <material name="black"><color rgba="0.0 0.0 0.0 1.0"/></material>
  <material name="grey"><color rgba="0.5 0.5 0.5 1.0"/></material>

  <xacro:macro name="box_inertia" params="m w h d">
    <inertial>
      <mass value="${m}"/>
      <inertia ixx="${(m/12) * (h*h + d*d)}" ixy="0.0" ixz="0.0" 
               iyy="${(m/12) * (w*w + d*d)}" iyz="0.0" 
               izz="${(m/12) * (w*w + h*h)}"/>
    </inertial>
  </xacro:macro>

  <xacro:macro name="cylinder_inertia" params="m r h">
    <inertial>
      <mass value="${m}"/>
      <inertia ixx="${(m/12) * (3*r*r + h*h)}" ixy="0.0" ixz="0.0" 
               iyy="${(m/12) * (3*r*r + h*h)}" iyz="0.0" 
               izz="${(m/2) * (r*r)}"/>
    </inertial>
  </xacro:macro>

  <!-- ========================================== -->
  <!-- 2. ROBOT BASE CHASSIS                      -->
  <!-- ========================================== -->
  <link name="base_footprint"/>

  <joint name="base_footprint_joint" type="fixed">
    <parent link="base_footprint"/>
    <child link="base_link"/>
    <origin xyz="0 0 0.1" rpy="0 0 0"/>
  </joint>

  <link name="base_link">
    <visual>
      <geometry><box size="0.5 0.3 0.15"/></geometry>
      <material name="blue"/>
    </visual>
    <collision>
      <geometry><box size="0.5 0.3 0.15"/></geometry>
    </collision>
    <xacro:box_inertia m="5.0" w="0.5" h="0.3" d="0.15"/>
  </link>

  <!-- ========================================== -->
  <!-- 3. WHEELS (4-Wheel Diff Drive)             -->
  <!-- ========================================== -->
  <xacro:macro name="wheel" params="prefix x_reflect y_reflect">
    <joint name="${prefix}_wheel_joint" type="continuous">
      <parent link="base_link"/>
      <child link="${prefix}_wheel"/>
      <origin xyz="${x_reflect*0.18} ${y_reflect*0.18} -0.05" rpy="${-pi/2} 0 0"/>
      <axis xyz="0 0 1"/>
    </joint>

    <link name="${prefix}_wheel">
      <visual>
        <geometry><cylinder radius="0.1" length="0.05"/></geometry>
        <material name="black"/>
      </visual>
      <collision>
        <geometry><cylinder radius="0.1" length="0.05"/></geometry>
      </collision>
      <xacro:cylinder_inertia m="0.5" r="0.1" h="0.05"/>
    </link>
  </xacro:macro>

  <xacro:wheel prefix="front_left"  x_reflect="1"  y_reflect="1" />
  <xacro:wheel prefix="front_right" x_reflect="1"  y_reflect="-1" />
  <xacro:wheel prefix="rear_left"   x_reflect="-1" y_reflect="1" />
  <xacro:wheel prefix="rear_right"  x_reflect="-1" y_reflect="-1" />

  <!-- ========================================== -->
  <!-- 4. SIMULATED SENSORS                       -->
  <!-- ========================================== -->

  <!-- LiDAR Frame & Gazebo Sensor -->
  <link name="laser_frame">
    <visual>
      <geometry><cylinder radius="0.05" length="0.05"/></geometry>
      <material name="grey"/>
    </visual>
    <xacro:cylinder_inertia m="0.1" r="0.05" h="0.05"/>
  </link>

  <joint name="laser_joint" type="fixed">
    <parent link="base_link"/>
    <child link="laser_frame"/>
    <origin xyz="0.15 0 0.1" rpy="0 0 0"/>
  </joint>

  <gazebo reference="laser_frame">
    <sensor name="gpu_lidar" type="gpu_lidar">
      <pose>0 0 0 0 0 0</pose>
      <topic>scan</topic>
      <update_rate>10</update_rate>
      <ray>
        <scan>
          <horizontal>
            <samples>640</samples>
            <resolution>1</resolution>
            <min_angle>-3.14159</min_angle>
            <max_angle>3.14159</max_angle>
          </horizontal>
        </scan>
        <range>
          <min>0.12</min>
          <max>12.0</max>
          <resolution>0.01</resolution>
        </range>
      </ray>
      <always_on>1</always_on>
      <visualize>true</visualize>
    </sensor>
  </gazebo>

  <!-- OAK-D Lite Depth Camera Frame & Gazebo Sensor -->
  <link name="oak_d_lite_frame">
    <visual>
      <geometry><box size="0.02 0.1 0.03"/></geometry>
      <material name="black"/>
    </visual>
    <xacro:box_inertia m="0.05" w="0.02" h="0.1" d="0.03"/>
  </link>

  <joint name="camera_joint" type="fixed">
    <parent link="base_link"/>
    <child link="oak_d_lite_frame"/>
    <origin xyz="0.23 0 0.03" rpy="0 0 0"/>
  </joint>

  <gazebo reference="oak_d_lite_frame">
    <sensor name="camera" type="rgbd_camera">
      <pose>0 0 0 0 0 0</pose>
      <topic>camera</topic>
      <update_rate>5</update_rate> <!-- lowerd this to 5 for performance can change to 30 for real comparisons -->
      <camera>
        <horizontal_fov>1.274</horizontal_fov>
        <image>
          <width>640</width>
          <height>480</height>
          <format>R8G8B8</format>
        </image>
        <clip>
          <near>0.1</near>
          <far>10.0</far>
        </clip>
      </camera>
      <always_on>1</always_on>
    </sensor>
  </gazebo>

  <!-- ========================================== -->
  <!-- 5. GAZEBO DIFF DRIVE SYSTEMS PLUGIN        -->
  <!-- ========================================== -->
  <gazebo>
    <plugin filename="ignition-gazebo-diff-drive-system" name="ignition::gazebo::systems::DiffDrive">
      <left_joint>front_left_wheel_joint</left_joint>
      <left_joint>rear_left_wheel_joint</left_joint>
      <right_joint>front_right_wheel_joint</right_joint>
      <right_joint>rear_right_wheel_joint</right_joint>
      <wheel_separation>0.36</wheel_separation>
      <wheel_radius>0.1</wheel_radius>
      <odom_publish_frequency>30</odom_publish_frequency>
      <topic>cmd_vel</topic>
      <odom_topic>odom</odom_topic>
      <tf_topic>tf</tf_topic>
      <frame_id>odom</frame_id>
      <child_frame_id>base_footprint</child_frame_id>
    </plugin>

    <!-- Essential plugin to publish all moving joint positions to ROS 2 -->
    <plugin filename="ignition-gazebo-joint-state-publisher-system" name="ignition::gazebo::systems::JointStatePublisher">
      <topic>joint_states</topic>
    </plugin>
  </gazebo>

</robot>